Workbook
Name Table1: #REF!
Name ___thinkcellf7gEwppKqUWVmG8WHzQ68g: #REF!
Name ___thinkcellGv_HMPayz0.PxVwiQe5IHg: #REF!
Name ___thinkcellsxsFZEKfu0KTlYCYIuITaA: #REF!
Name ___thinkcellUJcvPfgxy0Cqr_m8uCJCKA: #REF!
Name ___thinkcellY0P34UIewEePiRhx5hmEzA: #REF!
Name ___utc: #REF!
Name \_: #REF!
Name \a: #N/A
Name A: #REF!
Name A_Interface_IPoFEGE.EthREDPort: #REF!
Name A_Interface_IPoFEGE.IP_Path: #REF!
Name AA: #REF!
Name AAEspinos: #REF!
Name Abis_Interface_eGBTS.IP_Path: #REF!
Name Abis_Interface_IPoFEGE.IP_PATH: #REF!
Name adaFASFQAF: #REF!
Name afasfsgg: #REF!
Name Andra_pradesh: #REF!
Name ARBO001: #REF!
Name AREA: '[1]Fishbone Validation'!$D$3:$D$6
Name Area_Cat: #REF!
Name asas: #REF!
Name asd: #REF!
Name asdas: #REF!
Name asdasdasfvsaf: #REF!
Name asdasfafqf: #REF!
Name asdasfasfasf: #REF!
Name ASDASFASFQ: #REF!
Name asdfas: #REF!
Name asdfasf: #REF!
Name asdS: #REF!
Name asfasdf: #REF!
Name asfasfaf: #REF!
Name asfassd: #REF!
Name asfdsf: #REF!
Name asfsgdfhgjdh: #REF!
Name asfzxc: #REF!
Name asgthaththtth: #REF!
Name AUGPORTUTIL: #REF!
Name Availability: #REF!
Name BAND: #REF!
Name BATCH1TO5: #REF!
Name BATCH4TO5: #REF!
Name batch6: #REF!
Name batch7new: #REF!
Name BINONDO: #REF!
Name BLDG_TYPE: #REF!
Name BLOOD: #REF!
Name BoardList: #REF!
Name BOQ: #REF!
Name BOQA: #REF!
Name BRY: #REF!
Name BSC_Clock_Configuration.Configure_IP_Clock_Server: #REF!
Name BUDGET: #REF!
Name BUILD: #REF!
Name BY_NATURE_OF_BUS: #REF!
Name CABEX: #REF!
Name CABINET_SPACE: #REF!
Name cards: #REF!

Sheet IRUP SITELIST
A1: =SUBTOTAL(3,A4:A1047896) -> 6 | D1: =SUBTOTAL(3,D4:D1047896) -> 6 | N1: =SUBTOTAL(3,N4:N1010) -> 6 | Q1: =SUBTOTAL(9,Q4:Q1047896) -> 2326.6 | R1: =SUBTOTAL(9,R4:R1047896) -> 657.25 | AP1: PERMITTING | CB1: =SUBTOTAL(9,CB4:CB1009) -> 4.75 | CC1: =SUBTOTAL(9,CC4:CC1009) -> 19
A2: MIGRATION PLAN DATE2957 | B2: STATUS | D2: AREA | E2: LATITUDE | F2: LONGITUDE | G2: CITY | H2: PROVINCE | I2: CSZ | J2: APM ASSIGNED | K2: QTR | L2: WBS CODE | M2: SITE NO | N2: SITE NAME | O2: ARCHITYPE | P2: TONNES CLASSIFICATION | Q2: APPROX TONS | R2: DESIGN TONS | S2: OVERALL MILESTONE | T2: OVERALL PROGRESS | U2: DESIGN WEEK TARGET | V2: DESIGN ORIGINAL TARGET | W2: DESIGN REVISED TARGET COMPLETION | X2: DESIGN STATUS | Y2: SURVEY START | Z2: SURVEY DONE DATE | AA2: DESIGN COMPLETION | AB2: DESIGN SUBMISSION | AC2: DESIGN APPROVED | AD2: DESIGN REMARKS/ ISSUE | AE2: ISP/OSP | AF2: TOTAL WORKING DAYS | AG2: NO. OF MH ACTUAL | AH2: MH ACCESSIBLE | AI2: MH N/ ACCESSIBLE | AJ2: ASPHALTED | AK2: CEMENTED | AL2: BRICKS | AM2: MH INSIDE BLDG | AN2: DESIGN PROGRESS | AO2: PERMITTING WEEK TARGET | AP2: PERMITTING TARGET COMPLETION | AQ2: NEW PERMITTING TARGET | AR2: PERMITTING GENERAL STAUS | AS2: HOA SUBMITTED | AT2: HOA SECURED | AU2: HOA START | AV2: HOA END | AW2: DEVELOPER SUBMITTED | AX2: DEVELOPER secured | AY2: DEVELOPER START | AZ2: DEVELOPER END | BA2: BRGY SUBMITTED | BB2: BRGY PERMIT SECURED | BC2: BARANGAY START | BD2: BRGY END | BE2: LGU PERMIT SUBMITTED | BF2: LGU PERMIT SECURED | BG2: LGU START | BH2: LGU END | BI2: TRAFFIC submitted | BJ2: TRAFFIC PERMIT SECURED | BK2: TRAFFIC START | BL2: TRAFFIC END | BM2: DPWH submitted | BN2: DPWH SECURED | BO2: DPWH START | BP2: DPWH END | BQ2: PERMITTING ISSUE / REMARKS | BR2: PERMITTING PROGESS | BS2: EXTRACTION TARGET START WEEK | BT2: EXTRACTION TARGET START DATE | BU2: REVISED START WEEK | BV2: REVISED EXTRACTION START DATE | BW2: EXTRACTION DONE TARGET WEEK | BX2: EXTRACTION TARGET DONE DATE | BY2: REVISED EXTRACTION DONE DATE | BZ2: REVISION REMARKS | CA2: EXTRACTION START | CB2: EXCAVATION TEAM QUANTITY | CC2: EXTRACTION TEAM QUANTITY | CD2: EXTRACTION DONE DAYS | CE2: SUBCON | CF2: ISP/OSP | CG2: PS NAME | CH2: EXTRACTION STATUS | CI2: EXTRACTION PROGRESS | CJ2: EXTRACTION REMARKS | CK2: ISP EXTRACTION MONTH | CL2: OSP EXTRACTION MONTH | CM2: TOTAL MANHOLE | CN2: CIVIL WORKS MH | CO2: DEWATERING MH | CP2: NO DEWATERING MH | CQ2: TOTAL MANHOLE EXTRACTED | CR2: MANHOLE EXTRACTED GAP | CS2: ISP EXTRACTED | CT2: OSP EXTRACTED | CU2: TOTAL TONS EXTRACTED | CV2: EXTRACTION DONE
A3: Column1 | B3: STATUS | C3: Column2 | D3: AREA | E3: LATITUDE | F3: LONGITUDE | G3: CITY | H3: PROVINCE | I3: CSZ | J3: APM ASSIGNED | K3: QTR | L3: WBS CODE | M3: SITE NO | N3: SITE NAME | O3: ARCHITYPE | P3: TONNES CLASSIFICATION | Q3: APPROX TONS | R3: DESIGN TONS | S3: OVERALL MILESTONE | T3: OVERALL PROGRESS | U3: DESIGN WEEK TARGET | V3: DESIGN ORIGINAL TARGET | W3: DESIGN REVISED TARGET COMPLETION | X3: DESIGN STATUS | Y3: SURVEY START | Z3: SURVEY DONE DATE | AA3: DESIGN COMPLETION | AB3: DESIGN SUBMISSION | AC3: DESIGN APPROVED | AD3: DESIGN REMARKS/ ISSUE | AE3: ISP/OSP | AF3: TOTAL WORKING DAYS | AG3: NO. OF MH ACTUAL22 | AH3: MH ACCESSIBLE2 | AI3: MH N/ ACCESSIBLE2 | AJ3: ASPHALTED2 | AK3: CEMENTED2 | AL3: BRICKS | AM3: MH INSIDE BLDG | AN3: DESIGN PROGRESS | AO3: PERMITTING WEEK TARGET | AP3: PERMITTING TARGET COMPLETION | AQ3: NEW PERMITTING TARGET | AR3: PERMITTING GENERAL STAUS | AS3: HOA SUBMITTED | AT3: HOA SECURED | AU3: HOA START | AV3: HOA END | AW3: DEVELOPER SUBMITTED | AX3: DEVELOPER Secured | AY3: DEVELOPER START | AZ3: DEVELOPER END | BA3: BRGY SUBMITTED | BB3: BRGY PERMIT SECURED | BC3: BARANGAY START | BD3: BRGY END | BE3: LGU PERMIT SUBMITTED | BF3: LGU PERMIT SECURED | BG3: LGU START | BH3: LGU END | BI3: TRAFFIC submitted | BJ3: TRAFFIC PERMIT SECURED | BK3: TRAFFIC START | BL3: TRAFFIC END | BM3: DPWH submitted | BN3: DPWH SECURED | BO3: DPWH START | BP3: DPWH END | BQ3: PERMITTING ISSUE | BR3: PERMITTING PROGESS | BS3: EXTRACTION TARGET START WEEK | BT3: EXTRACTION TARGET START DATE | BU3: REVISED START WEEK | BV3: REVISED EXTRACTION START DATE | BW3: EXTRACTION DONE TARGET WEEK | BX3: EXTRACTION TARGET DONE DATE | BY3: REVISED EXTRACTION DONE DATE | BZ3: REVISION REMARKS | CA3: EXTRACTION START | CB3: EXCAVATION TEAM QUANTITY | CC3: TEAM QUANTITY | CD3: EXTRACTION DONE DAYS | CE3: SUBCON2 | CF3: ISP/OSP2 | CG3: PS NAME2 | CH3: EXTRACTION STATUS | CI3: EXTRACTION PROGRESS | CJ3: EXTRACTION REMARKS | CK3: Column6 | CL3: Column8 | CM3: TOTAL MANHOLE | CN3: CIVIL WORKS MH | CO3: DEWATERING MH | CP3: NO DEWATERING MH | CQ3: TOTAL MANHOLE OPENNED | CR3: MANHOLE OPENNED GAP | CS3: ISP EXTRACTED | CT3: OSP EXTRACTED | CU3: TOTAL TONS EXTRACTED | CV3: EXTRACTION DONE
A4: 46235 | B4: RFE | C4: PART OF 233 | D4: GMM | E4: 14.578856 | F4: 121.00113 | G4: Manila City | H4: Metropolitan Manila | I4: South Manila | J4: Jessa | K4: Q1 | L4: T-37262327I-1-GMM-00002 | M4: IRUP0001 | N4: Paco Exchange | O4: Exchange-L | P4: =IF(OR(NOT(ISNUMBER(Q4)),Q4=0),"NO DATA",IF(Q4<10,"<10 TONNES",">=10 TONNES")) -> >=10 TONNES | Q4: 454.2 | R4: 121.59 | S4: =IF(CH4="CANCELLED","CANCELLED",IF(CV4<>"","EXTRACTION DONE",IF(CH4="ON GOING EXTRACTION","ON GOING EXTRACTION",IF(AR4="RFE","READY FOR EXTRACTION",IF(AR4="ON GOING PERMITTING","ON GOING PERMITTING",IF(AC4<>"","DESIGN APPROVED",IF(AB4<>"","DESIGN SUBMITTED",IF(AA4<>"","DESIGN COMPLETED",IF(Z4<>"","ON GOING DESIGN",IF(Y4<>"","ON GOING SURVEY","NOT STARTED")))))))))) -> ON GOING EXTRACTION | T4: =IFERROR((AN4*33%)+(BR4*27%)+(CI4*40%),0) -> 0.68529412 | U4: =IF(V4>0,WEEKNUM(V4,1)&"-"&YEAR(V4),"") -> 38-2026 | V4: 46282 | W4: =V4 -> 46282 | X4: =IF(AD4>0,"DESIGN WITH CONCERN",IF(AC4>0,"DESIGN APPROVED",IF(AB4>0,"DESIGN FOR APPROVAL",IF(AA4>0,"DESIGN FOR SUBMISSION",IF(Z4>0,"ON GOING DESIGN",IF(Y4>0,"ON GOING SURVEY","FOR SURVEY")))))) -> DESIGN APPROVED | Y4: 46275 | Z4: 46281 | AA4: 46282 | AB4: 46282 | AC4: 46282 | AE4: Both | AF4: =IF(AA4-Y4<0,0,AA4-Y4) -> 7 | AG4: =AH4+AI4 -> 136 | AH4: 72 | AI4: 64 | AJ4: 31 | AK4: 33 | AL4: 0 | AN4: =COUNT(Y4:AC4)/5 -> 1 | AO4: =IF(AQ4>0,WEEKNUM(AQ4,1)&"-"&YEAR(AQ4),"") -> 42-2026 | AP4: 46307 | AQ4: 46307 | AR4: =IF(AA4="","WAITING FOR PLAN",IF(AU4="","PERMITTING NOT STARTED",IF(BR4>=100%,"RFE","ON GOING PERMITTING"))) -> RFE | AS4: NA | AT4: NA | AU4: 46316 | AV4: 46316 | AW4: NA | AX4: NA | AY4: 46316 | AZ4: 46316 | BA4: 68 | BB4: 68 | BC4: 46266 | BD4: 46283 | BE4: 1 | BF4: 1 | BG4: 46286 | BH4: 46307 | BI4: 2 | BJ4: 2 | BK4: 46294 | BL4: 46307 | BM4: 1 | BN4: 1 | BO4: 46289 | BP4: 46307 | BQ4: 13-Oct-26 - RFE Sites | BR4: =IFERROR((COUNT(BD4)*40%)+(COUNT(BL4)*20%)+(COUNT(BH4)*10%)+(COUNT(BP4)*10%)+(COUNT(AV4)*10%)+(COUNT(AZ4)*10%),0) -> 1 | BS4: =IF(BT4>0,WEEKNUM(BT4,1)&"-"&YEAR(BT4),"") -> 42-2026 | BT4: =AP4+3 -> 46310 | BU4: =IF(BV4>0,WEEKNUM(BV4,1)&"-"&YEAR(BV4),"") -> 42-2026 | BV4: 46311 | BW4: =IF(BX4>0,WEEKNUM(BX4,1)&"-"&YEAR(BX4),"") -> 47-2026 | BX4: =IF(CA4="",BV4+CD4,CA4+CD4) -> 46343.424 | BY4: 46340 | BZ4: 10/29/26: Partially Completed on Nov 14. Continuation on 2027 | CA4: 46311 | CB4: =IF(AI4<>0,CC4*0.25,0) -> 0.75 | CC4: 3 | CD4: =IF(R4=0,IFERROR(Q4/(CC4)/1.25,0),IFERROR(R4/(CC4)/1.25,0)) -> 32.424 | CE4: DIMARCO | CF4: BOTH | CG4: Jed, Mark, Ron, Adrian, Jerome, Naj, Alain | CH4: =IF(CA4="","NOT STARTED",IF(CA4<>"","ON GOING EXTRACTION",IF(CV4<>"","EXTRACTION COMPLETED"))) -> ON GOING EXTRACTION | CI4: =IFERROR(CQ4/CM4,0) -> 0.21323529 | CJ4: 10/27/26: 2,847.9 kg extracted: ~Cluster 3 (2pcs MH Open/Dewater) MH01 - MH04 • 300 pairs (48.52m) = 120.35 kg • 600 pairs (92.89m) = 199.6 kg • 1200 pairs (91.93m) = 388.9 kg • 2100 pairs (91.51m) = 642.3 kg • 2400 pairs (182.9m) = 1,496.75 kg ~ For continuation on Wednesday (October 28 shift) at Paco Site. 10/23/26: 4,566.20 kg extracted: ~Cluster 3 (4pcs MH Open/Dewater) MH92 - MH94 • 1500 pairs = 659.30 kg • 1800 pairs = 763.55 kg • 2400 pairs = 3,143.35 kg 10/24/26: 2,758.25 kg extracted: ~Cluster 3 (5pcs MH Open/Dewater) MH01 - MH92 • 1500 pairs (171.28m) = 875.75 kg • 1800 pairs (170m) = 1,055.95 kg MH01 - MH57 • 400 pairs (3.29m) = 5.05 kg • 600 pairs (35.32m) = 79.75 kg • 900 pairs (6.71m) = 21.9 kg • 1200 pairs (2m) = 8.70 kg • 1500 pairs (60.88m) = 346.1 kg • 1800 pairs (6.26m) = 32.85 kg • 2100 pairs (18.72m) = 132.20 kg • 2400 pairs (25.47m) = 200 kg 10/20/26: 1,272.75kg extracted: • >600 pairs = 1,233.45kg • <600 pairs = 39.3 kg ~ For Cluster 7: •Copper cable near EOL (Near 7-11; After MH 243), still cannot pull the cable. Used push rod to trace the cable route, it was stopped midway due to clogged duct. •MH38 still cannot open the manhole. Even used the Lever/Jack system, not able to access the MH ~For Cluster 6: •MH20 - Tried to open the Manhole again using various tools and method, still, cannot access the Manhole Cover. •MH23 - MH25, For verification the next day if the remaining copper was cut and extractable or not. 10/19/26: 1,157.85 kg extracted - For Cluster 7: •MH12054 - EOL, still cannot pull the cable even though the copepr at the other was cut. •MH2096 - MH2107, can't extract one span of copper cable •MH2117 - MH2106, MH can't open, need additional tools to open MH. 10/16/26: For Cluster 6: MH2172, MH2162, MH2151, visible but hard to open due to the manholes are not opened for a long time and was stuck. For Cluster 7: Copper lines from the following span are not removed due to cables are stuck (can't pull): MH12054 - End of Cable Line MH2186 - MH3068 Total of 2 Span and 4 MH opened | CK4: 46296 | CL4: 46296 | CM4: =AG4 -> 136 | CN4: =AI4 -> 64 | CO4: 15 | CQ4: 29 | CR4: =CM4-CQ4 -> 107 | CS4: 1.67 | CT4: 25.9 | CU4: =CS4+CT4 -> 27.57
A5: 46235 | B5: RFE | C5: PART OF 233 | D5: NLZ | E5: 14.957886 | F5: 120.90429 | G5: Baliuag | H5: Bulacan | I5: Bulacan | J5: Limwell | K5: Q1 | L5: T-37262327I-1-NLZ-00005 | M5: IRUP0002 | N5: Baliuag Sub-Exchange | O5: Sub-Exchange-S | P5: =IF(OR(NOT(ISNUMBER(Q5)),Q5=0),"NO DATA",IF(Q5<10,"<10 TONNES",">=10 TONNES")) -> >=10 TONNES | Q5: 60.2 | R5: 22.88 | S5: =IF(CH5="CANCELLED","CANCELLED",IF(CV5<>"","EXTRACTION DONE",IF(CH5="ON GOING EXTRACTION","ON GOING EXTRACTION",IF(AR5="RFE","READY FOR EXTRACTION",IF(AR5="ON GOING PERMITTING","ON GOING PERMITTING",IF(AC5<>"","DESIGN APPROVED",IF(AB5<>"","DESIGN SUBMITTED",IF(AA5<>"","DESIGN COMPLETED",IF(Z5<>"","ON GOING DESIGN",IF(Y5<>"","ON GOING SURVEY","NOT STARTED")))))))))) -> READY FOR EXTRACTION | T5: =IFERROR((AN5*33%)+(BR5*27%)+(CI5*40%),0) -> 0.6 | U5: =IF(V5>0,WEEKNUM(V5,1)&"-"&YEAR(V5),"") -> 38-2026 | V5: 46279 | W5: =V5 -> 46279 | X5: =IF(AD5>0,"DESIGN WITH CONCERN",IF(AC5>0,"DESIGN APPROVED",IF(AB5>0,"DESIGN FOR APPROVAL",IF(AA5>0,"DESIGN FOR SUBMISSION",IF(Z5>0,"ON GOING DESIGN",IF(Y5>0,"ON GOING SURVEY","FOR SURVEY")))))) -> DESIGN APPROVED | Y5: 46275 | Z5: 46276 | AA5: 46279 | AB5: 46279 | AC5: 46279 | AE5: Both | AF5: =IF(AA5-Y5<0,0,AA5-Y5) -> 4 | AG5: =AH5+AI5 -> 28 | AH5: 12 | AI5: 16 | AJ5: 13 | AK5: 3 | AL5: 0 | AN5: =COUNT(Y5:AC5)/5 -> 1 | AO5: =IF(AQ5>0,WEEKNUM(AQ5,1)&"-"&YEAR(AQ5),"") -> 44-2026 | AP5: 46325 | AQ5: 46325 | AR5: =IF(AA5="","WAITING FOR PLAN",IF(AU5="","PERMITTING NOT STARTED",IF(BR5>=100%,"RFE","ON GOING PERMITTING"))) -> RFE | AS5: NA | AT5: NA | AU5: 46316 | AV5: 46316 | AW5: NA | AX5: NA | AY5: 46316 | AZ5: 46316 | BA5: 5 | BB5: 5 | BC5: 46287 | BD5: 46295 | BE5: 1 | BF5: 1 | BG5: 46303 | BH5: 46321 | BI5: 1 | BJ5: 1 | BK5: 46301 | BL5: 46303 | BM5: 1 | BN5: 1 | BO5: 46301 | BP5: 46324 | BQ5: Oct 23 DPWH Bulacan 1st DEO Remarks: waiting to release receipt of Cash Bond and following up routing of the permit. Validity: 72 calendar days once secured. Contact name - Engr. Jose Federico Estigoy Contact number - 09260414377 Brgy: 5/5 LGU: 1/1 Traffic: 1/1 DPWH: 0/1 (Ongoing) DPWH Bulacan 1st DEO Remarks: waiting to release receipt of Cash Bond and following up routing of the permit. Validity: 72 calendar days once secured. Contact name - Engr. Jose Federico Estigoy Contact number - 09260414377 Brgy: 5/5 LGU: 1/1 Traffic: 1/1 DPWH: 0/1 (Ongoing) 19-Oct-26 Advanced Copy of the signed Baliuag LGU Permit. The hardcopy will be picked up by Engr. Billy here in Baliuag City Engr'g Office and will be released at the business center. As per City Engr., make sure to have a close coordination with BCTMO and Barangay. Contact Person: Engr. Billy James John C. Punzalan Contact #: 09057892343 Validity: 1yr Work hours: 6pm-6am Barangay: 5/5 LGU: 0/1 (ongoing) Traffic: 1/1 DPWH: 0/1 (Ongoing) 15-Oct-26 Baliuag City Hall MH #: MH001-MH016, MH018-MH029 Remarks: LGU Permit paid, 35,270.27. As per Engr. Billy, kindly wait for further instructions later if permit can possibly be released today. According to him, Baliuag City Business Center (one stop shop) is open even on Fridays but release of permit still depends if it will be signed immediately by the City Engineer. Since Baliuag City Hall is close during Fridays, they can only release permits which were signed the day prior. Contact Person: Engr. Billy James John C. Punzalan Contact #: 09057892343 Barangay: 5/5 LGU: 0/1 (ongoing) Traffic: 1/1 DPWH: 0/1 (Ongoing) Thank you! ROW Officer - Maria Ivory C. Suarez 14-Oct-26 Baliuag Sub Exchange Grantor: Baliuag City Hall MH #: MH001-MH016, MH018-MH029 Remarks: Advance copy of the OP amounting to 35,270.27. Official OP will possibly be released either later or tomorrow. As per advise, once paid, issuance of permit will be released the following day. Contact Person: Engr. Billy James John C. Punzalan Contact #: 09057892343 Barangay: 5/5 LGU: 0/1 (ongoing Traffic: 1/1 DPWH: 0/1 (Ongoing) Thank you! ROW Officer - Maria Ivory C. Suarez 12-Oct-26 DPWH Bulacan 1st DEO Remarks: Submitted Notarized Authorization Letter and Terms and Condition. Following up the status of the docs that are for routing. Waiting for the feedback of Engr. Joes and Engr. Charles. Brgy: 5/5 LGU: 0/1 (ongoing) Traffic: 1/1 DPWH: 0/1 (Ongoing) Thank you! ---- 8-Oct-26 ( Baliuag City Hall Remarks: Application has been received. As per Engr. Billy Punzalan, it will be endorsed to the Engr'g Office in 1-2 days for assessment. Once Engr'g Office received the documents, inspection will take place if there will be no dependecy. Informed them that I will follow up by Wednesday. Please see photo as proof of submission. Note: They required notarization for the BOM. Thank you!) --- (BTMO MH #: MH001-MH016, MH018-MH029 Remarks: Secured Traffic Clearance. No payment fee. As per Sir Ramil, remarks on the permit must be followed otherwise, cancellation may be applied. Contact Person: Ramil Ubungin Contact #: 09423162142 Barangay: 5/5 LGU: 0/1 Traffic: 1/1 DPWH: 0/1 (Ongoing) Thank you! ROW Officer - Maria Ivory C. Suarez) --- Baliuag Sub Exchange Grantor: DPWH Bulacan 1st DEO Remarks: Ongoing DPWH inspection with Sir Lincoln, Engr. Joes and Engr. Charles. Thank you! --- 1-Oct-26 Brgy. Sabang - Here at brgy Hall Sabang. Waiting for the budget and BC to be released. Thank you. Brgy. Treasurer Melchor Encarnacion - 09326338204 Brgy. Secretary Sarah Cruz - 09331538844 -- 30-Sep-26 (BTMO - Coordinated with Sir Ramil Ubungin, Admin Aide of BTMO. He provided the list of requirements for the traffic clearance. LOI BC Authorization Letter from PLDT ID of the Authorized Person List of Names of the people who will do the implementation. As per him, no fee for the traffic clearance. Ramil Ubungin - 09423162144 (8am-5pm/M-F only) ---- (Brgy. Bagong Nayon - As per Brgy. Sec., they are still waiting for the feedback of some of the councils. Also, brgy chairman has prior engagement. As per Sec., they will give feedback either tomorrow or latest is Friday.)Brgy. Poblacion - Secured BC. Free of charge. Was advised to do courtesy call prior mob. 28/09/2026 DPWH - inquire requirements in DPWH Bulacan 1st DEO for the Baliuag site. Coordinated with Engr. Joes. List of requirements were provided. Engr. Joes of the Maintenance Dept. - 09260414377 | BR5: =IFERROR((COUNT(BD5)*40%)+(COUNT(BL5)*20%)+(COUNT(BH5)*10%)+(COUNT(BP5)*10%)+(COUNT(AV5)*10%)+(COUNT(AZ5)*10%),0) -> 1 | BS5: =IF(BT5>0,WEEKNUM(BT5,1)&"-"&YEAR(BT5),"") -> 45-2026 | BT5: =AP5+3 -> 46328 | BU5: =IF(BV5>0,WEEKNUM(BV5,1)&"-"&YEAR(BV5),"") | BW5: =IF(BX5>0,WEEKNUM(BX5,1)&"-"&YEAR(BX5),"") | BZ5: 10/29/26: Sir Jayson's feedback today | CB5: =IF(AI5<>0,CC5*0.25,0) -> 0.5 | CC5: 2 | CD5: =IF(R5=0,IFERROR(Q5/(CC5)/1.25,0),IFERROR(R5/(CC5)/1.25,0)) -> 9.152 | CE5: ASSURE | CH5: =IF(CA5="","NOT STARTED",IF(CA5<>"","ON GOING EXTRACTION",IF(CV5<>"","EXTRACTION COMPLETED"))) -> NOT STARTED | CI5: =IFERROR(CQ5/CM5,0) -> 0 | CK5: 46296 | CL5: 46296 | CM5: =AG5 -> 28 | CN5: =AI5 -> 16 | CR5: =CM5-CQ5 -> 28 | CU5: =CS5+CT5 -> 0
A6: 46235 | B6: RFE | C6: PART OF 233 | D6: NLZ | E6: 14.797833 | F6: 120.87748 | G6: Bulacan | H6: Bulacan | I6: Bulacan | J6: Limwell | K6: Q1 | L6: T-37262327I-1-NLZ-00004 | M6: IRUP0003 | N6: Bulacan Sub-Exchange/RSU | O6: Sub-Exchange-S | P6: =IF(OR(NOT(ISNUMBER(Q6)),Q6=0),"NO DATA",IF(Q6<10,"<10 TONNES",">=10 TONNES")) -> >=10 TONNES | Q6: 26.8 | R6: 1.54 | S6: =IF(CH6="CANCELLED","CANCELLED",IF(CV6<>"","EXTRACTION DONE",IF(CH6="ON GOING EXTRACTION","ON GOING EXTRACTION",IF(AR6="RFE","READY FOR EXTRACTION",IF(AR6="ON GOING PERMITTING","ON GOING PERMITTING",IF(AC6<>"","DESIGN APPROVED",IF(AB6<>"","DESIGN SUBMITTED",IF(AA6<>"","DESIGN COMPLETED",IF(Z6<>"","ON GOING DESIGN",IF(Y6<>"","ON GOING SURVEY","NOT STARTED")))))))))) -> ON GOING EXTRACTION | T6: =IFERROR((AN6*33%)+(BR6*27%)+(CI6*40%),0) -> 0.6 | U6: =IF(V6>0,WEEKNUM(V6,1)&"-"&YEAR(V6),"") -> 38-2026 | V6: 46282 | W6: =V6 -> 46282 | X6: =IF(AD6>0,"DESIGN WITH CONCERN",IF(AC6>0,"DESIGN APPROVED",IF(AB6>0,"DESIGN FOR APPROVAL",IF(AA6>0,"DESIGN FOR SUBMISSION",IF(Z6>0,"ON GOING DESIGN",IF(Y6>0,"ON GOING SURVEY","FOR SURVEY")))))) -> DESIGN APPROVED | Y6: 46275 | Z6: 46275 | AA6: 46282 | AB6: 46282 | AC6: 46282 | AE6: Both | AF6: =IF(AA6-Y6<0,0,AA6-Y6) -> 7 | AG6: =AH6+AI6 -> 9 | AH6: 1 | AI6: 8 | AJ6: 8 | AK6: 0 | AL6: 0 | AN6: =COUNT(Y6:AC6)/5 -> 1 | AO6: =IF(AQ6>0,WEEKNUM(AQ6,1)&"-"&YEAR(AQ6),"") -> 43-2026 | AP6: 46318 | AQ6: 46318 | AR6: =IF(AA6="","WAITING FOR PLAN",IF(AU6="","PERMITTING NOT STARTED",IF(BR6>=100%,"RFE","ON GOING PERMITTING"))) -> RFE | AS6: NA | AT6: NA | AU6: 46316 | AV6: 46316 | AW6: NA | AX6: NA | AY6: 46316 | AZ6: 46316 | BA6: 2 | BB6: 2 | BC6: 46286 | BD6: 46301 | BE6: 1 | BF6: 1 | BG6: 46302 | BH6: 46303 | BI6: 1 | BJ6: 1 | BK6: 46303 | BL6: 46302 | BM6: 1 | BN6: 1 | BO6: 46302 | BP6: 46303 | BQ6: 8-Oct-26 - RFE Sites 6-Oct-26 Brgy Matungao Secured Permit Contact name: Brgy Sec contact number: 09205650575 Validity of Permit - 1 month Permit fee - 1k Remarks:/Report: Permit Secured Brgy - 1/2 LGU - 0/1 TRAFFIC - DPWH - ---- 29-Sep-26 Claster 1 Bulakan bulacan MH001, MH002 Grantor NAme - Brgy San Jose Contact name Gemma G. Mabanta (Brgy Secretary) Contact number - 09151046402 Validity of Permit - 6 months / 1 yr Permit fee: 2000 OR Remarks:/Report Submitted LOI for paynent tomorrow The brgy captain is in seminar for follow up tomorrow | BR6: =IFERROR((COUNT(BD6)*40%)+(COUNT(BL6)*20%)+(COUNT(BH6)*10%)+(COUNT(BP6)*10%)+(COUNT(AV6)*10%)+(COUNT(AZ6)*10%),0) -> 1 | BS6: =IF(BT6>0,WEEKNUM(BT6,1)&"-"&YEAR(BT6),"") -> 44-2026 | BT6: =AP6+3 -> 46321 | BU6: =IF(BV6>0,WEEKNUM(BV6,1)&"-"&YEAR(BV6),"") -> 44-2026 | BV6: 46324 | BW6: =IF(BX6>0,WEEKNUM(BX6,1)&"-"&YEAR(BX6),"") -> 44-2026 | BX6: =IF(CA6="",BV6+CD6,CA6+CD6) -> 46324.616 | BY6: 46330 | BZ6: 10/29/26: DD: 10/29 | CA6: 46324 | CB6: =IF(AI6<>0,CC6*0.25,0) -> 0.5 | CC6: 2 | CD6: =IF(R6=0,IFERROR(Q6/(CC6)/1.25,0),IFERROR(R6/(CC6)/1.25,0)) -> 0.616 | CE6: ASSURE | CF6: BOTH | CG6: lincoln, Jeff, Marvin, Darren | CH6: ON GOING EXTRACTION | CI6: =IFERROR(CQ6/CM6,0) -> 0 | CK6: 46296 | CL6: 46296 | CM6: =AG6 -> 9 | CN6: =AI6 -> 8 | CR6: =CM6-CQ6 -> 9 | CU6: =CS6+CT6 -> 0
A7: 46235 | B7: RFE | C7: PART OF 233 | D7: GMM | E7: 14.516502 | F7: 121.23834 | G7: Morong | H7: Rizal | I7: CTAABMT | K7: Q2 | L7: T-37262327I-1-GMM-00015 | M7: IRUP0004 | N7: Morong | O7: Exchange-S | P7: =IF(OR(NOT(ISNUMBER(Q7)),Q7=0),"NO DATA",IF(Q7<10,"<10 TONNES",">=10 TONNES")) -> <10 TONNES | Q7: 8.9 | R7: 2.71 | S7: =IF(CH7="CANCELLED","CANCELLED",IF(CV7<>"","EXTRACTION DONE",IF(CH7="ON GOING EXTRACTION","ON GOING EXTRACTION",IF(AR7="RFE","READY FOR EXTRACTION",IF(AR7="ON GOING PERMITTING","ON GOING PERMITTING",IF(AC7<>"","DESIGN APPROVED",IF(AB7<>"","DESIGN SUBMITTED",IF(AA7<>"","DESIGN COMPLETED",IF(Z7<>"","ON GOING DESIGN",IF(Y7<>"","ON GOING SURVEY","NOT STARTED")))))))))) -> DESIGN APPROVED | T7: =IFERROR((AN7*33%)+(BR7*27%)+(CI7*40%),0) -> 0.33 | U7: =IF(V7>0,WEEKNUM(V7,1)&"-"&YEAR(V7),"") -> 38-2026 | V7: 46282 | W7: =V7 -> 46282 | X7: =IF(AD7>0,"DESIGN WITH CONCERN",IF(AC7>0,"DESIGN APPROVED",IF(AB7>0,"DESIGN FOR APPROVAL",IF(AA7>0,"DESIGN FOR SUBMISSION",IF(Z7>0,"ON GOING DESIGN",IF(Y7>0,"ON GOING SURVEY","FOR SURVEY")))))) -> DESIGN APPROVED | Y7: 46282 | Z7: 46282 | AA7: 46284 | AB7: 46284 | AC7: 46284 | AE7: Both | AF7: =IF(AA7-Y7<0,0,AA7-Y7) -> 2 | AG7: =AH7+AI7 -> 20 | AH7: 1 | AI7: 19 | AJ7: 19 | AK7: 0 | AL7: 0 | AN7: =COUNT(Y7:AC7)/5 -> 1 | AO7: =IF(AQ7>0,WEEKNUM(AQ7,1)&"-"&YEAR(AQ7),"") -> 49-2026 | AP7: 46371 | AQ7: 46357 | AR7: =IF(AA7="","WAITING FOR PLAN",IF(AU7="","PERMITTING NOT STARTED",IF(BR7>=100%,"RFE","ON GOING PERMITTING"))) -> PERMITTING NOT STARTED | BQ7: PENDING | BR7: =IFERROR((COUNT(BD7)*40%)+(COUNT(BL7)*20%)+(COUNT(BH7)*10%)+(COUNT(BP7)*10%)+(COUNT(AV7)*10%)+(COUNT(AZ7)*10%),0) -> 0 | BS7: =IF(BT7>0,WEEKNUM(BT7,1)&"-"&YEAR(BT7),"") | BU7: =IF(BV7>0,WEEKNUM(BV7,1)&"-"&YEAR(BV7),"") | BW7: =IF(BX7>0,WEEKNUM(BX7,1)&"-"&YEAR(BX7),"") -> 1-1900 | BX7: =IF(CA7="",BV7+CD7,CA7+CD7) -> 1.084 | CB7: =IF(AI7<>0,CC7*0.25,0) -> 0.5 | CC7: 2 | CD7: =IF(R7=0,IFERROR(Q7/(CC7)/1.25,0),IFERROR(R7/(CC7)/1.25,0)) -> 1.084 | CH7: =IF(CA7="","NOT STARTED",IF(CA7<>"","ON GOING EXTRACTION",IF(CV7<>"","EXTRACTION COMPLETED"))) -> NOT STARTED | CI7: =IFERROR(CQ7/CM7,0) -> 0 | CM7: =AG7 -> 20 | CN7: =AI7 -> 19 | CR7: =CM7-CQ7 -> 20 | CU7: =CS7+CT7 -> 0
A8: 46235 | B8: RFE | C8: PART OF 233 | D8: GMM | E8: 14.494219 | F8: 121.29121 | G8: Tanay | H8: Rizal | I8: CTAABMT | J8: Jessa | K8: Q1 | L8: T-37262327I-1-GMM-00003 | M8: IRUP0005 | N8: Tanay CO | O8: Exchange-M | P8: =IF(OR(NOT(ISNUMBER(Q8)),Q8=0),"NO DATA",IF(Q8<10,"<10 TONNES",">=10 TONNES")) -> >=10 TONNES | Q8: 156.8 | R8: 17.44 | S8: =IF(CH8="CANCELLED","CANCELLED",IF(CV8<>"","EXTRACTION DONE",IF(CH8="ON GOING EXTRACTION","ON GOING EXTRACTION",IF(AR8="RFE","READY FOR EXTRACTION",IF(AR8="ON GOING PERMITTING","ON GOING PERMITTING",IF(AC8<>"","DESIGN APPROVED",IF(AB8<>"","DESIGN SUBMITTED",IF(AA8<>"","DESIGN COMPLETED",IF(Z8<>"","ON GOING DESIGN",IF(Y8<>"","ON GOING SURVEY","NOT STARTED")))))))))) -> ON GOING EXTRACTION | T8: =IFERROR((AN8*33%)+(BR8*27%)+(CI8*40%),0) -> 0.62857143 | U8: =IF(V8>0,WEEKNUM(V8,1)&"-"&YEAR(V8),"") -> 38-2026 | V8: 46282 | W8: =V8 -> 46282 | X8: =IF(AD8>0,"DESIGN WITH CONCERN",IF(AC8>0,"DESIGN APPROVED",IF(AB8>0,"DESIGN FOR APPROVAL",IF(AA8>0,"DESIGN FOR SUBMISSION",IF(Z8>0,"ON GOING DESIGN",IF(Y8>0,"ON GOING SURVEY","FOR SURVEY")))))) -> DESIGN APPROVED | Y8: 46275 | Z8: 46276 | AA8: 46282 | AB8: 46282 | AC8: 46282 | AE8: Both | AF8: =IF(AA8-Y8<0,0,AA8-Y8) -> 7 | AG8: =AH8+AI8 -> 14 | AH8: 4 | AI8: 10 | AJ8: 10 | AK8: 0 | AL8: 0 | AN8: =COUNT(Y8:AC8)/5 -> 1 | AO8: =IF(AQ8>0,WEEKNUM(AQ8,1)&"-"&YEAR(AQ8),"") -> 43-2026 | AP8: 46318 | AQ8: 46318 | AR8: =IF(AA8="","WAITING FOR PLAN",IF(AU8="","PERMITTING NOT STARTED",IF(BR8>=100%,"RFE","ON GOING PERMITTING"))) -> RFE | AS8: NA | AT8: NA | AU8: 46316 | AV8: 46316 | AW8: NA | AX8: NA | AY8: 46316 | AZ8: 46316 | BA8: 4 | BB8: 4 | BC8: 46287 | BD8: 46315 | BE8: 1 | BF8: 1 | BG8: 46290 | BH8: 46315 | BI8: 1 | BJ8: 1 | BK8: 46290 | BL8: 46290 | BM8: 1 | BN8: 1 | BO8: 46290 | BP8: 46315 | BQ8: Oct 23 DPWH Rizal 2nd DEO - For pick up Official permit with DPWH Dry seal. The first DPWH provided was Only an Advance copy for Lgu Tanay application. However Engr. Rick is not around Already RFE DPWH Rizal 2nd DEO - For pick up Official permit with DPWH Dry seal. The first DPWH provided was Only an Advance copy for Lgu Tanay application. However Engr. Rick is not around Already RFE 20-Oct-26 Tanay Lgu - Follow up the Order of payment to the assessment officer, Arch. Angela 19-Oct-26 Tanay Lgu, Waiting for Engr. Vitas to submit DPWH permit and Acquire Order of Payment 15-Oct-26 DPWH Engr. Rick is currently on sick leave and is in the hospital. However, I have already requested an advance copy of the permit, even without the official DPWH dry seal, just so we can present it to the LGU of Tanay as proof that our permit has already been approved by DPWH. This way, the LGU of Tanay can at least consider our request and allow us to proceed with the payment process. and Engr. Rick agreed to speak to the Office of the Building Official of Tanay as proof that we have DPWH Approval ( If Necessary.) and Received call from Tanay Water District Asking for additional requirements such as: ID's of Personnel and Exact Working Date. 14-Oct-26 With Engr. Johnrich Head Officer of the Office of the Building Official Tanay Rizal. Done Discussion/Negotiation With Engr. John, And Agreed to Accept and Have an Advance assessment of our Lgu Permit Application while waiting for the DPWH Permit. However the person Incharge for The Assessment of our Documents Submitted is on Seminar. 13-Oct-26 Tanay Exchange Grantor: Ongoing Sign and Seal Plan and Civil/Electronincs Permit. 7-Oct-26 DPWH Rizal 2nd DEO -Waiting for Engr. Rick's availability to submit His Requested Edited LOI. Removing Repair and Restoration Words. 6-Oct-26 Ongoing Site inspection with DPWH RIZAL 2ND DEO --- 2-Oct-26 Tanay Exchange C1 DPWH Tanay 2nd Rizal District .- Already spoke to Engr.Nick Regarding 10 overlayed Manholes Along Jurisdiction of DPWH, Which are Requested for Manholes raising.. As per him We will meet on Monday Next week to talk what remedy or Help they could offer us to Expedite the Permit acquisition. 30-Sep-26 -DPWH Rizal 2nd DEO. - Pick DPWH Request Letter to PLDT Manhole Raising. With District Engr. Signatory. --- 29-Sep-26 (Tanay Exchange C1 Grantor: Tanay LGU . @Office of the Municipal Mayor, Follow up Plan Proposal Evaluation.) As per the Mayor's office Staff, Plan Proposal Already Done Evaluation of the mayor and Endorsed to Municipal Engineering office. 28-Sep-26 Tanay Exchange Gantors: DPWH/Tanay Lgu (Tanay Exchange Grantor: DPWH Rizal 2nd DEO- They need PLDT’s details so they can properly address the letter regarding the manhole raising. As per Engr. Rick, the letter should be addressed directly to the principal client and not to the contractor. LOI must be Notarized following/Attached all Requirements prior for receiving of LOI. @⁨FH Mam Nena Feliciano⁩ ma'am) 25-Sep-26 For Submission of LOI address to District Engr. and follow up Engr . Rick for The additional requirements, However Engr. rick is on Site. as per his Subordinate follow up on Monday, possibly at DWPH Pasig. Acquired Engr.'s Contact Number. 25/09/2026 Tanay Exchange Grantor: DPWH Tanay 2nd District Rizal Remarks: They will no longer allow excavation and restoration only. They want the missing manholes to be installed flush with the road surface because they said that excavating and restoring the road would compromise its durability and could eventually cause potholes. 10 missing manholes out of 14 manholes. Engr. Rick advised me to visit his office at DWPH PASIG for further Explanation. | BR8: =IFERROR((COUNT(BD8)*40%)+(COUNT(BL8)*20%)+(COUNT(BH8)*10%)+(COUNT(BP8)*10%)+(COUNT(AV8)*10%)+(COUNT(AZ8)*10%),0) -> 1 | BS8: =IF(BT8>0,WEEKNUM(BT8,1)&"-"&YEAR(BT8),"") -> 44-2026 | BT8: =AP8+3 -> 46321 | BU8: =IF(BV8>0,WEEKNUM(BV8,1)&"-"&YEAR(BV8),"") -> 44-2026 | BV8: 46323 | BW8: =IF(BX8>0,WEEKNUM(BX8,1)&"-"&YEAR(BX8),"") -> 46-2026 | BX8: =IF(CA8="",BV8+CD8,CA8+CD8) -> 46336.952 | BY8: 46333 | BZ8: 10/29/26: Partially Completed on Nov 7. Continuation on 2027 | CA8: 46323 | CB8: =IF(AI8<>0,CC8*0.25,0) -> 0.25 | CC8: 1 | CD8: =IF(R8=0,IFERROR(Q8/(CC8)/1.25,0),IFERROR(R8/(CC8)/1.25,0)) -> 13.952 | CE8: DIMARCO | CF8: BOTH | CG8: Jed, Mark, Ron, Adrian, Jerome, Naj, Alain | CH8: =IF(CA8="","NOT STARTED",IF(CA8<>"","ON GOING EXTRACTION",IF(CV8<>"","EXTRACTION COMPLETED"))) -> ON GOING EXTRACTION | CI8: =IFERROR(CQ8/CM8,0) -> 0.071428571 | CK8: 46296 | CL8: 46296 | CM8: =AG8 -> 14 | CN8: =AI8 -> 10 | CQ8: 1 | CR8: =CM8-CQ8 -> 13 | CS8: 2.5778 | CU8: =CS8+CT8 -> 2.5778
A9: 46235 | B9: RFE | C9: PART OF 233 | D9: GMM | E9: 14.67066 | F9: 120.94582 | G9: Malabon City | H9: Metropolitan Manila | I9: CaMaNaVa | J9: Dan | K9: Q1 | L9: T-37262327I-1-GMM-00012 | M9: IRUP0006 | N9: Malabon Exchange | O9: Exchange-M | P9: =IF(OR(NOT(ISNUMBER(Q9)),Q9=0),"NO DATA",IF(Q9<10,"<10 TONNES",">=10 TONNES")) -> >=10 TONNES | Q9: 127.4 | R9: 34.73 | S9: =IF(CH9="CANCELLED","CANCELLED",IF(CV9<>"","EXTRACTION DONE",IF(CH9="ON GOING EXTRACTION","ON GOING EXTRACTION",IF(AR9="RFE","READY FOR EXTRACTION",IF(AR9="ON GOING PERMITTING","ON GOING PERMITTING",IF(AC9<>"","DESIGN APPROVED",IF(AB9<>"","DESIGN SUBMITTED",IF(AA9<>"","DESIGN COMPLETED",IF(Z9<>"","ON GOING DESIGN",IF(Y9<>"","ON GOING SURVEY","NOT STARTED")))))))))) -> ON GOING PERMITTING | T9: =IFERROR((AN9*33%)+(BR9*27%)+(CI9*40%),0) -> 0.492 | U9: =IF(V9>0,WEEKNUM(V9,1)&"-"&YEAR(V9),"") -> 39-2026 | V9: 46289 | W9: =V9 -> 46289 | X9: =IF(AD9>0,"DESIGN WITH CONCERN",IF(AC9>0,"DESIGN APPROVED",IF(AB9>0,"DESIGN FOR APPROVAL",IF(AA9>0,"DESIGN FOR SUBMISSION",IF(Z9>0,"ON GOING DESIGN",IF(Y9>0,"ON GOING SURVEY","FOR SURVEY")))))) -> DESIGN APPROVED | Y9: 46279 | Z9: 46283 | AA9: 46289 | AB9: 46289 | AC9: 46295 | AE9: Both | AF9: =IF(AA9-Y9<0,0,AA9-Y9) -> 10 | AG9: =AH9+AI9 -> 50 | AH9: 31 | AI9: 19 | AJ9: 1 | AK9: 18 | AL9: 0 | AN9: =COUNT(Y9:AC9)/5 -> 1 | AO9: =IF(AQ9>0,WEEKNUM(AQ9,1)&"-"&YEAR(AQ9),"") -> 45-2026 | AP9: 46333 | AQ9: 46333 | AR9: =IF(AA9="","WAITING FOR PLAN",IF(AU9="","PERMITTING NOT STARTED",IF(BR9>=100%,"RFE","ON GOING PERMITTING"))) -> ON GOING PERMITTING | AS9: NA | AT9: NA | AU9: 46316 | AV9: 46316 | AW9: NA | AX9: NA | AY9: 46316 | AZ9: 46316 | BA9: 9 | BB9: 9 | BC9: 46293 | BD9: 46307 | BE9: 1 | BG9: 46293 | BI9: 1 | BK9: 46293 | BQ9: Cluster 2 – Malabon Cluster 2 – Caloocan Exchange Co. Cluster 1 – Caloocan Cluster 1 – Grace Park Remarks: Submitted the signed and sealed plans, BOM, and Gantt Chart to the LGU. Engnr Kweenie advised that she will inform me once the Order of Payment is available, as she still needs to review the excavation permit application. I also submitted the documents to Engr. Carlo for the LGU’s No Objection approval. OCT 22 Cluster 2 – Malabon Cluster 2 – Caloocan Exchange Co. Cluster 1 – Caloocan Cluster 1 – Grace Park Remarks: Submitted the signed and sealed plans, BOM, and Gantt Chart to the LGU. Engnr Kweenie advised that she will inform me once the Order of Payment is available, as she still needs to review the excavation permit application. I also submitted the documents to Engr. Carlo for the LGU’s No Objection approval. 12-Oct-26 Brgy Flores Remarks : Here at brgy Flores done payment for brgy permit STATUS : Permit Secured Permit Validity : Until finish Amount : 300 Permit fee (OR) 3000 cash Bond Note : the barangay will provide excavation cashbond form Total Amount : 3,300 BRGY - 7/7 LGU - 0/1 DPWH - 0/1 TRAFFIC - 0/1 --- 8-Oct-26 (Brgy Concepcion @brgy concepcion waiting for brgy secretary for payment of brgy permit) LGU Malabon Remarks: @ LGU Malabon Engineering Department and spoke with Ms. Divina Ramos to ask about the requirements needed for the LGU permit. She advised that we need to submit an LOI addressed to the City Mayor, indicating the barangays where we will be conducting the project. We also need to secure the Contractor’s Tax for excavation and the DPWH Permit. Contact person : divina b. Ramos Contact no: 09225217854 Designation : administrative officer 2 ----- 5-Oct-26 -Brgy baritan Remarks : done payment for brgy permit - Permit secured Permit fee : 2000 (AR) OR/AR Permit Validity : 3 months Contact person : zander Contact no: 0943640308 Brgy - 4/7 Lgu - 0/1 Dpwh - 0-1 Traffice 0-1 --- 1-Oct-26 -Brgy san Agustin Contact Name: Benilda S. Legarda Designation - brgy secretary Contact no: 09063474254 Validity permit - 4 months Permit Fee - 1500 (OR) Cashbond - 10,000 (SOA) NOTE: We can get the cash bond back once we’re done and everything is properly completed. They still need to inspect the work, so they’ll also need to see the before-and-after photos of the site. Remarks : done payment for brgy permit of San Agustin - permit Secured Brgy - 2/6 LGU - 0/1 TRAFFIC - 0/1 DPWH - 0/1 30-Sep-26 Brgy. Baritan Following up on the barangay application. I’m just waiting for the Barangay Secretary to confirm the amount fee for the barangay permit. They asked me to come back at 2:00 PM so I can speak with him directly. ---- 29/09/2026 (Chief Officer Saint James T. Lopez of CTPMO stated that a permit will not be issued without the DPWH Permit, which must be applied for with the DPWH and followed by an inspection. He recommends conducting implementation once the permit is granted, preferably between 8pm to 5am on weekdays, and at any time during weekends. Meanwhile, during the work, the manhole should be covered with a 1-inch-thick steel plate to ensure safety.) (Malabon C2 Grantor: Barangay Hulong Duhat MH Nos.: MH 057, MH 058, MH 044, MH 045, MH 045 Submitted the LOI and plans for Barangay Hulong Duhat. as per Barangay Secretary, Ms. Desiree O. Bersales, there is a cash bond of ₱5,000 that needs to be paid. The cash bond will be refundable after six (6) months, as the barangay will conduct another inspection once the work has been completed to ensure that the excavation and restoration work has been properly done. The permit fee is ₱300, which covers all the manholes that will be constructed. Permit Validity: 6 months Refundable Cash Bond: ₱5,000 Permit Fee: ₱300 Contact Person: Desiree O. Bersales, Barangay Secretary Contact No.: 0924 571 3655) --- (DPWH–Malabon–Navotas District Engineering Office. Ms. Honey Tejadilla (0908 370 7858) advised that the manholes (MH) located along E. Rodriguez St., with MH Nos. SB051, SB050, SB049, and SB048, were just restored this year. They cannot guarantee that excavation will be permitted because the road works are still under a surety bond with the subcontractor who completed the restoration. She suggested submitting a Request Letter regarding our activity at the said location. The request will then be reviewed, and they will provide a response based on the discussion with their District Engineer. She also suggested submitting the following documents: 1.Program of Works and Detailed Unit Price Analysis 2.Geotagged Pictures 3.Utility Layout Plan 4.Cross-Sectional Plan and Specifications showing the proposed utility to be embedded in the existing road 5.Precedence Diagram Method 6.Notarized Authorization Letter from the Agency/Company) ----- -Claster 1 Bulakan bulacan MH001, MH002 Grantor NAme - Brgy San Jose Contact name Gemma G. Mabanta (Brgy Secretary) Contact number - 09151046402 Validity of Permit - 6 months / 1 yr Permit fee: 2000 OR Remarks:/Report Submitted LOI for paynent tomorrow The brgy captain is in seminar for follow up tomorrow 28/09/2026 San Agustin I already submitted the LOI and plan for the Barangay Permit, as advised by Ma’am Benilda, the Barangay Secretary, regarding the manhole opening She mentioned that they require a ₱10,000 cash bond, which is refundable once the work is completed and the site is properly restored. We just need to provide before-and-after photos of the site when we process the refund. The Barangay Permit fee is ₱1,500, and the permit is valid for 3 months. Contact person: Ma’am Benilda S. Legarda Barangay Secretary 0906 347 4254 | BR9: =IFERROR((COUNT(BD9)*40%)+(COUNT(BL9)*20%)+(COUNT(BH9)*10%)+(COUNT(BP9)*10%)+(COUNT(AV9)*10%)+(COUNT(AZ9)*10%),0) -> 0.6 | BS9: =IF(BT9>0,WEEKNUM(BT9,1)&"-"&YEAR(BT9),"") -> 46-2026 | BT9: =AP9+3 -> 46336 | BU9: =IF(BV9>0,WEEKNUM(BV9,1)&"-"&YEAR(BV9),"") -> 46-2026 | BV9: 46337 | BW9: =IF(BX9>0,WEEKNUM(BX9,1)&"-"&YEAR(BX9),"") -> 48-2026 | BX9: =IF(CA9="",BV9+CD9,CA9+CD9) -> 46350.892 | BY9: =IF(CA9="",BV9+CD9,CA9+CD9) -> 46350.892 | CB9: =IF(AI9<>0,CC9*0.25,0) -> 0.5 | CC9: 2 | CD9: =IF(R9=0,IFERROR(Q9/(CC9)/1.25,0),IFERROR(R9/(CC9)/1.25,0)) -> 13.892 | CG9: Frederick, Randy, Mjay, Loyd, Rafael, Winston, Mathew | CH9: =IF(CA9="","NOT STARTED",IF(CA9<>"","ON GOING EXTRACTION",IF(CV9<>"","EXTRACTION COMPLETED"))) -> NOT STARTED | CI9: =IFERROR(CQ9/CM9,0) -> 0 | CM9: =AG9 -> 50 | CN9: =AI9 -> 19 | CR9: =CM9-CQ9 -> 50 | CU9: =CS9+CT9 -> 0
A10: 46235 | B10: RFE | C10: PART OF 233 | D10: GMM | E10: 14.756092 | F10: 121.04702 | G10: Caloocan City | H10: Metropolitan Manila | I10: CaMaNaVa | J10: Dan | K10: Q1 | L10: T-37262327I-1-GMM-00001 | M10: IRUP0007 | N10: Kalookan Exchange CO | O10: Exchange-M | P10: =IF(OR(NOT(ISNUMBER(Q10)),Q10=0),"NO DATA",IF(Q10<10,"<10 TONNES",">=10 TONNES")) -> >=10 TONNES | Q10: 156.8 | R10: 93.1 | S10: =IF(CH10="CANCELLED","CANCELLED",IF(CV10<>"","EXTRACTION DONE",IF(CH10="ON GOING EXTRACTION","ON GOING EXTRACTION",IF(AR10="RFE","READY FOR EXTRACTION",IF(AR10="ON GOING PERMITTING","ON GOING PERMITTING",IF(AC10<>"","DESIGN APPROVED",IF(AB10<>"","DESIGN SUBMITTED",IF(AA10<>"","DESIGN COMPLETED",IF(Z10<>"","ON GOING DESIGN",IF(Y10<>"","ON GOING SURVEY","NOT STARTED")))))))))) -> ON GOING PERMITTING | T10: =IFERROR((AN10*33%)+(BR10*27%)+(CI10*40%),0) -> 0.438 | U10: =IF(V10>0,WEEKNUM(V10,1)&"-"&YEAR(V10),"") -> 39-2026 | V10: 46291 | W10: =V10 -> 46291 | X10: =IF(AD10>0,"DESIGN WITH CONCERN",IF(AC10>0,"DESIGN APPROVED",IF(AB10>0,"DESIGN FOR APPROVAL",IF(AA10>0,"DESIGN FOR SUBMISSION",IF(Z10>0,"ON GOING DESIGN",IF(Y10>0,"ON GOING SURVEY","FOR SURVEY")))))) -> DESIGN APPROVED | Y10: 46288 | Z10: 46288 | AA10: 46291 | AB10: 46291 | AC10: 46300 | AE10: OSP only | AF10: =IF(AA10-Y10<0,0,AA10-Y10) -> 3 | AG10: =AH10+AI10 -> 61 | AH10: 58 | AI10: 3 | AJ10: 2 | AK10: 0 | AL10: 1 | AN10: =COUNT(Y10:AC10)/5 -> 1 | AO10: =IF(AQ10>0,WEEKNUM(AQ10,1)&"-"&YEAR(AQ10),"") -> 45-2026 | AP10: 46329 | AQ10: 46329 | AR10: =IF(AA10="","WAITING FOR PLAN",IF(AU10="","PERMITTING NOT STARTED",IF(BR10>=100%,"RFE","ON GOING PERMITTING"))) -> ON GOING PERMITTING | AS10: NA | AT10: NA | AU10: 46316 | AV10: 46316 | AW10: NA | AX10: NA | AY10: 46316 | AZ10: 46316 | BA10: 1 | BB10: 13 | BC10: 46294 | BE10: 2 | BF10: 1 | BG10: 46294 | BI10: 1 | BJ10: 1 | BK10: 46294 | BL10: 46307 | BM10: 1 | BO10: 46297 | BQ10: 14-Oct-26 BRGY LONGOS Remarks : done payment for brgy longos PERMIT FEE: 500 (OR) VALIDITY PERMIT : 5 MONTHS STATUS : BRGY PERMIT SECURED BRGY - 2/3 LGU - 0/1 DPWH - 0/1 TRAFFIC - 0/1 13-Oct-26 Brgy longos REMARKS: As per the Barangay Secretary, only the three (3) manholes listed above are under their jurisdiction, based on their site inspection. The other manholes are reportedly under the jurisdiction of Barangay 14, Kalookan. I was advised to verify the remaining manholes with Barangay 14 first before they can release the permit. ---- 12-Oct-26 DPSTM South Caloocan Activity: Permit Secured until October 31, 2026 ( Renewable free) --- 8-Oct-26 Brgy 9 Contact Details: Sec Micah Contact Number: 09672906364 Permit Fee: 2k AR with 5k Cashbond (Refundable) Validity Permit: 3 months Remarks: PERMIT ACQUIRED - PLEASE SUBMIT JOB ORDER AND ID’s OF PERSONNEL TO BRGY ONCE DEPLOYED (STRICTLY COMPLIANCE FOR SAFETY PURPOSE). MAKE SURE TO ALWAYS BRING COPY OF PERMIT. Brgy - 4/4 LGU - 0/1 Traffic - 0/1 Dpwh - 0/1 7-Oct-26 (Brgy. Longos -- Follow up application, Sec Eugene is in the meeting.) (Brgy. Tonsuya Remarks: As per Ma’am Tin, Clerk Officer, we need to comply first with the required documents/requirements being requested by the barangay. These include the following: Plan List of personnel No Objection from the Malabon LGU According to the barangay, they have an existing barangay ordinance requiring these documents before they can proceed with the manhole inspection and release. ) --- (DPSTM Done submitting and discussing our Traffic Management Plan with Architect Nitz. As per him, our application is currently being routed for signature. Once the permit is signed, we will need to pay ₱50.00 for the Documentary Stamp at the New Caloocan City Hall. The permit is expected to be released by Monday or Tuesday, once the signing and payment are completed.) ---- Brgy. 3 Contact Name: Chairman Manuel Estolano Contact Number: 09164387475 Designation: Brgy Chairman Permit Validity: 3 months Permit Fee: 5k AR Remarks: STRICTLY NO WORK OR WORK-RELATED ACTIVITIES SHALL BE CONDUCTED FROM OCTOBER 30, 2026 UNTIL NOVEMBER 4, 2026. ACTIVITIES WILL RESUME ON NOVEMBER 5. OPENING OF MANHOLES CAN ACCESS FROM OCT.7 to OCT 29, 2026 IF UNDONE, WILL RESUME ON NOVEMBER 5. Brgy - 4/4 LGU - 0/1 Traffic - 0/1 Dpwh - 0/1 --- 5-Oct-26 - (Brgy 14 Contact Name: Jeus Marco Galvez Contact Number: 09426061406 Designation: Brgy Secretary Permit Validity: 6 months Permit Fee: 2k AR to follow OR by Friday Validity 6 months Remarks: Permit Acquired. Please inform Brgy ahead of time before deployment. And the team must log in first. Brgy - 2/5 LGU - 0/1 Traffic - 0/1 Dpwh - 0/1) --- (Brgy. Tinajeros MH # : MH2347 MH2346 MH2345 MH2344 MH2348 MH2349 Remarks : done payment of brgy tinajeros permit - secured Permit Permit fee - 500 (OR) Permit Validity : 1 month Contact Person: roselle Vibar Designation : brgy clerk Contact no: 09325377664 BRGY - 2/3 LGU - 0/1 TRAFFIC - 0/1 DPWH - 0/1) ---- Brgy 12 Contact Name: Earl Gene Cruz Contact Number: 09941646819 Designation: Brgy Admin Permit Validity: 6 months for Opening manhole, 2-3weeks for Excavtion Permit Permit Fee: 4k AR with Cash Bond 5k (Refundable) Total of 9,000 Remarks: -permit acquired, negotiated the fee from ₱12,000 down to ₱4,000 for 2 overlayed manhole plus ₱5k cash bond refundable after the excavated areas are fully restored. - Excavation Permit will be issued once the team is deployed just present the receipt. The activity must be completed within a maximum of 2-3 weeks, including the full restoration of the affected areas. - Can proceed on accessible manholes. Team must inform and log in at the barangay office before starting any work. - Prioritize Pusit Street for the excavation and complete the restoration, as delivery trucks use the road to access the public market. --- 2-Oct-26 (Submitted the revised plan for the visible manhole only. Since I was unable to catch Engr. William today as he is currently conducting a site inspection, he requested that we leave our application with their Admin Office. Engr. William will retrieve the application on Monday and provide me with an update regarding its status. For the manhole with civil works, we will apply online once we have the pending requirements from the Design Team, particularly the cross-sectional section and Precedence Diagram Method (PDM). For the Legal Team requirements, the Secretary’s Certificate/Authorization is expected to be released earlier on Monday, as advised by the Legal Team.) --- (Brgy. 4 Contact Details: Sec. Priscila Tolentino Contact Number: 09150731787 Designation: Brgy Chairman Permit Validity: 6 months Permit Fee: 2k OR Remarks: Need to inform and log in first at the Barangay before proceeding with the implementation. Brgy - 0/4 LGU - 0/1 Traffic - 0/1 Dpwh - 0/1) --- (Brgy. Longos Remarks: LOI Submitted, For inspection of Brgy. Officials. Once inspection is done they will inform me for Payment Process. Need to apply LGU, PSTMO & DPWH under National Road. Barangay: 0/3 LGU: 0/1 PSTMO: 0/1 DPWH: 0/1) ---- Brgy Acacia remarks : for payment of brgy permit ----- 1-Oct-26 (Brgy.5 for MH 1025 Brgy.Sec.Imelda De Guzman 0936-7992309 donation of Php500 for their cleaning materials with AR. Validity one year during mob.their Brgy.Tanod will have to assist us and provide them their compensation for the services rendered. ) --- (Brgy.9 for MH 6947 LOI submitted as per Brgy. Capt.Edwin Galvez Brgy.9 tel# 878-4467 needed the following as attachments with our LOI 1).PLDT job order 2).PLDT authorization to Fiberhome to undertake said scope of works 3).duration of works 4)traffic management plan Permit fee-to be determine once above are complied.) -- Brgy. 1 Contact Name: Cherrie Ann (Secretary) Contact Number: 09056564324 Designation: Brgy Chairman Permit Validity: 6 months Permit Fee: 2k AR -- 30-Sep-26 (PUBLIC SAFETY AND TRAFFIC MANAGEMENT DEPARTMENT • Documents received by PSTMD. To follow: Submission of the following requirements: ◦ Barangay Permit ◦ MMDA Permit ◦ DPWH Permit ◦ NTP • As per Ma’am Dolly, we need to confirm with Arch. Nitz first if he will allow us to attend his meeting on Monday at 10:00 AM. • During meeting we need discuss the traffic flow and traffic management plan for our project. Engr assigned is required to attend the meeting. • PSTMD requires traffic personnel for the project, and their salary will be shouldered by us. • We also need to comply with the remaining requirements first to avoid any hold or delay in the application process. Contact Details: Architect Nitz Contact Number: 09988466746 ) ---- Brgy. Longos Remarks: As per Sec. Eugene, requested revisions to the LOI, indicating streets with manholes and their count under their jurisdiction. Advised to apply for a permit with CTPMO since it's under National Road. ---- 29-Sep-26 (Caloocan City Cluster 4 Brgy.14 for MH 6947 LOI submitted 09/29/26. Brgy.Sec.Jeus Marco Galvez 0942-6061406 permit fee Php2,000 per MH excavation with Brgy.ordinance.Permit tentative release date on Thurs.Oct.01/26. Remarks : MH 6947 is not accessible.) ----- (kalookan exchange City Cluster 1 Brgy. Acacia for MH6913 6910 6912 6905 LOI submitted 09/29/26. Brgy.staff. Ms. Sharmaine permit fee Php1,000 Remarks : permit will be release upon payment valid for 6 mos.) ----- (kalookan exchange City Cluster 1 Brgy. Tugatog for MH2339 2336 6905 2342 2343 2341 2337 2338 2340 LOI submitted 09/29/26. Brgy.staff. Ms. Juvy Barrios contact no:09493528341 permit fee and cash bond to be determine as soon as we give them the timeline of the implementation, working hours and implementation target completion Remarks: MH6909 not accssible Remarks :AR will be given up on payment ) Caloocan City Cluster 4 at Brgy.12 for MH 6945,6942,6944 & 6946 accessible MH and MH 6943 & 6941 not accessible MH along Dagat dagatan Ave.but unfortunately our LOI was not receive by the B.Sec.for the reason that once received they acknowledged said letter.Permit fee P2K per MH. Brgy.Sec.Melanie Forte Brgy.Ofc.# 0994-1646811 Remarks : Permit once paid for release. | BR10: =IFERROR((COUNT(BD10)*40%)+(COUNT(BL10)*20%)+(COUNT(BH10)*10%)+(COUNT(BP10)*10%)+(COUNT(AV10)*10%)+(COUNT(AZ10)*10%),0) -> 0.4 | BS10: =IF(BT10>0,WEEKNUM(BT10,1)&"-"&YEAR(BT10),"") -> 45-2026 | BT10: =AP10+3 -> 46332 | BU10: =IF(BV10>0,WEEKNUM(BV10,1)&"-"&YEAR(BV10),"") -> 46-2026 | BV10: 46335 | BW10: =IF(BX10>0,WEEKNUM(BX10,1)&"-"&YEAR(BX10),"") -> 49-2026 | BX10: =IF(CA10="",BV10+CD10,CA10+CD10) -> 46359.827 | BY10: =IF(CA10="",BV10+CD10,CA10+CD10) -> 46359.827 | CB10: =IF(AI10<>0,CC10*0.25,0) -> 0.75 | CC10: 3 | CD10: =IF(R10=0,IFERROR(Q10/(CC10)/1.25,0),IFERROR(R10/(CC10)/1.25,0)) -> 24.826667 | CG10: Frederick, Randy, Mjay, Loyd, Rafael, Winston, Mathew | CH10: =IF(CA10="","NOT STARTED",IF(CA10<>"","ON GOING EXTRACTION",IF(CV10<>"","EXTRACTION COMPLETED"))) -> NOT STARTED | CI10: =IFERROR(CQ10/CM10,0) -> 0 | CM10: =AG10 -> 61 | CN10: =AI10 -> 3 | CR10: =CM10-CQ10 -> 61 | CU10: =CS10+CT10 -> 0
